<?xml version="1.0"?>
<!-- Arm-only UR5 description used as robot_description for the picknplace ur5_rg2.
     Purpose: (1) feed MoveIt the standard-UR5 kinematics that ur5_rg2's arm matches
     exactly, and (2) provide the <ros2_control> block that the gz_ros2_control plugin
     (declared inside picknplace ur5_rg2/model.sdf) reads to claim the 6 arm joints by
     name. No gripper here — the RG2 is fixed/cosmetic and grasp is the DetachableJoint. -->
<robot xmlns:xacro="http://www.ros.org/wiki/xacro" name="$(arg name)">

  <xacro:arg name="name"      default="ur"/>
  <xacro:arg name="ur_type"   default="ur5"/>
  <xacro:arg name="tf_prefix" default=""/>

  <xacro:arg name="joint_limit_params"
    default="$(find ur_description)/config/$(arg ur_type)/joint_limits.yaml"/>
  <xacro:arg name="kinematics_params"
    default="$(find ur_description)/config/$(arg ur_type)/default_kinematics.yaml"/>
  <xacro:arg name="physical_params"
    default="$(find ur_description)/config/$(arg ur_type)/physical_parameters.yaml"/>
  <xacro:arg name="visual_params"
    default="$(find ur_description)/config/$(arg ur_type)/visual_parameters.yaml"/>

  <xacro:arg name="safety_limits"     default="false"/>
  <xacro:arg name="safety_pos_margin" default="0.15"/>
  <xacro:arg name="safety_k_position" default="20"/>

  <!-- Path to the controllers yaml; injected by the launch (gz_ros2_control <parameters>). -->
  <xacro:arg name="simulation_controllers" default=""/>

  <xacro:include filename="$(find ur_description)/urdf/ur_macro.xacro"/>
  <!-- Stock UR gz ros2_control macro — the SAME one the proven step2 stack uses. It
       exposes position+velocity+effort command interfaces; gz_ros2_control's
       GazeboSimSystem only actuates the joint when the velocity/effort interfaces are
       present (a position-only command interface registers but never drives physics —
       the JTC reference advances while the joint stays frozen). -->
  <xacro:include filename="$(find ur_simulation_gz)/urdf/ur_gz.ros2_control.xacro"/>

  <link name="world"/>

  <xacro:ur_robot
    name="$(arg name)"
    tf_prefix="$(arg tf_prefix)"
    parent="world"
    joint_limits_parameters_file="$(arg joint_limit_params)"
    kinematics_parameters_file="$(arg kinematics_params)"
    physical_parameters_file="$(arg physical_params)"
    visual_parameters_file="$(arg visual_params)"
    safety_limits="$(arg safety_limits)"
    safety_pos_margin="$(arg safety_pos_margin)"
    safety_k_position="$(arg safety_k_position)"
    force_abs_paths="true">
    <origin xyz="0 0 0" rpy="0 0 0"/>
  </xacro:ur_robot>

  <!-- ── RG2 gripper — COSMETIC visual-only ──────────────────────────────────────
       The OnRobot RG2 mounted on the flange, so the arm visibly carries its gripper.
       Fixed links, NEGLIGIBLE mass, and NO <collision>: the grasp is the
       DetachableJoint (fingers never actuated), and omitting collision keeps the
       ~0.2 m gripper from jamming into the belt during the flange-level grasp and
       leaves the verified arm control/planning untouched. Mount + finger transforms
       and meshes are taken verbatim from picknplace ur5_rg2/model.sdf. -->
  <xacro:property name="rg2_mesh"
    value="file://$(env HOME)/picknplace_ws/src/picknplace/urdf/ur5_rg2/meshes/visual/rg2"/>
  <xacro:macro name="rg2_cosmetic_link" params="name mesh *visual_origin">
    <link name="${name}">
      <visual>
        <xacro:insert_block name="visual_origin"/>
        <geometry><mesh filename="${rg2_mesh}/${mesh}"/></geometry>
      </visual>
      <inertial>
        <mass value="0.05"/>
        <inertia ixx="3e-5" iyy="3e-5" izz="3e-5" ixy="0" ixz="0" iyz="0"/>
      </inertial>
    </link>
  </xacro:macro>

  <!-- Mounted on tool0 (the real flange frame: +z = approach axis). The picknplace
       transforms were in ITS wrist_3 frame, which differs from stock ur_description's,
       so the gripper floated off the side; re-derived here relative to tool0 so the
       hand sits flush on the flange with the fingers extending along +z. -->
  <joint name="rg2_hand_joint" type="fixed">
    <parent link="tool0"/>
    <child link="rg2_hand"/>
    <origin xyz="0 0 0.0" rpy="0 -1.570796327 3.141592654"/>
  </joint>
  <xacro:rg2_cosmetic_link name="rg2_hand" mesh="hand.dae">
    <origin xyz="0 0 0" rpy="0 0 0"/>
  </xacro:rg2_cosmetic_link>

  <!-- Fingers are now REVOLUTE so they open/close to pinch the cube. Actuated by gz
       JointPositionController plugins (below), NOT ros2_control -> decoupled from the
       verified arm control and avoids the gripper-controller segfault. Driven via gz
       topics by the demonstrator (open on approach, close on the cube). Axes from
       picknplace (finger2 mirrored). -->
  <joint name="rg2_finger_joint1" type="revolute">
    <parent link="rg2_hand"/>
    <child link="rg2_leftfinger"/>
    <origin xyz="0.105 0.017 0" rpy="0 0 0"/>
    <axis xyz="0 0 1"/>
    <limit lower="-1.3" upper="1.3" effort="10.6" velocity="1.57"/>
    <dynamics damping="0.5" friction="0.1"/>
  </joint>
  <!-- leftfinger: visual mesh + a BOX collision approximating the blade so the
       finger physically stops at the cube (no more passing through it). Box spans the
       mesh bounds (local x -0.014..0.108, y ±0.0155, z ±0.010). High friction so the
       closed fingers actually hold the part by contact. -->
  <link name="rg2_leftfinger">
    <visual>
      <origin xyz="0 0 0" rpy="0 0 0"/>
      <geometry><mesh filename="${rg2_mesh}/finger.dae"/></geometry>
    </visual>
    <collision>
      <origin xyz="0.047 0 0" rpy="0 0 0"/>
      <geometry><box size="0.12 0.031 0.02"/></geometry>
      <surface>
        <friction><ode><mu>1.2</mu><mu2>1.2</mu2></ode></friction>
      </surface>
    </collision>
    <inertial>
      <mass value="0.05"/>
      <inertia ixx="3e-5" iyy="3e-5" izz="3e-5" ixy="0" ixz="0" iyz="0"/>
    </inertial>
  </link>

  <joint name="rg2_finger_joint2" type="revolute">
    <parent link="rg2_hand"/>
    <child link="rg2_rightfinger"/>
    <origin xyz="0.105 -0.017 0" rpy="0 0 0"/>
    <axis xyz="0 0 -1"/>
    <limit lower="-1.3" upper="1.3" effort="10.6" velocity="1.57"/>
    <dynamics damping="0.5" friction="0.1"/>
  </joint>
  <!-- rightfinger: mirror of leftfinger (visual flipped about x), same box collision. -->
  <link name="rg2_rightfinger">
    <visual>
      <origin xyz="0 0 0" rpy="3.141592653589793 0 0"/>
      <geometry><mesh filename="${rg2_mesh}/finger.dae"/></geometry>
    </visual>
    <collision>
      <origin xyz="0.047 0 0" rpy="0 0 0"/>
      <geometry><box size="0.12 0.031 0.02"/></geometry>
      <surface>
        <friction><ode><mu>1.2</mu><mu2>1.2</mu2></ode></friction>
      </surface>
    </collision>
    <inertial>
      <mass value="0.05"/>
      <inertia ixx="3e-5" iyy="3e-5" izz="3e-5" ixy="0" ixz="0" iyz="0"/>
    </inertial>
  </link>

  <!-- Grasp TCP at the RG2 fingertips (picknplace ur5_rg2 tool0 transform): this is the
       frame the IK drives to the belt, so the FINGERS reach the cube instead of the
       flange. Its +z axis = the wrist's +y = the gripper approach axis, so the existing
       top-down quaternion (frame +z -> world -z) makes the gripper point straight down. -->
  <joint name="rg2_tcp_joint" type="fixed">
    <parent link="tool0"/>
    <child link="rg2_tcp"/>
    <origin xyz="0 0 0.193" rpy="0 0 0"/>
  </joint>
  <link name="rg2_tcp"/>

  <!-- ros2_control on the 6 arm joints via the stock UR gz macro (position+velocity+effort
       command interfaces; gz_ros2_control needs them to actually drive the joints). The
       initial_positions spawn the arm already in the compact "up" pose so it never droops
       into the ground/conveyors during the launch window before the controller activates
       (a drooped floor-mounted UR5 jams its wrist through the floor -> effort saturates and
       it can't recover). The JTC then holds this pose from t=0. -->
  <xacro:ur_ros2_control
    name="$(arg name)"
    tf_prefix="$(arg tf_prefix)"
    initial_positions="${dict(
      shoulder_pan_joint=0.0,
      shoulder_lift_joint=-1.5708,
      elbow_joint=-1.5708,
      wrist_1_joint=-1.5708,
      wrist_2_joint=0.0,
      wrist_3_joint=0.0)}"/>

  <!-- gz_ros2_control plugin (this robot is SPAWNED from URDF via ros_gz_sim create, so the
       plugin must live in the URDF, not the world SDF). Starts the controller_manager. -->
  <gazebo>
    <plugin filename="gz_ros2_control-system"
            name="gz_ros2_control::GazeboSimROS2ControlPlugin">
      <parameters>$(arg simulation_controllers)</parameters>
    </plugin>

    <!-- RG2 finger position controllers (pure gz, decoupled from ros2_control).
         Commanded with a gz.msgs.Double target angle on each topic by the
         demonstrator: open on approach, close on the cube. -->
    <plugin filename="gz-sim-joint-position-controller-system"
            name="gz::sim::systems::JointPositionController">
      <joint_name>rg2_finger_joint1</joint_name>
      <topic>/rg2/finger1_cmd</topic>
      <p_gain>8.0</p_gain><i_gain>0.1</i_gain><d_gain>0.4</d_gain>
      <initial_position>0.0</initial_position>
    </plugin>
    <plugin filename="gz-sim-joint-position-controller-system"
            name="gz::sim::systems::JointPositionController">
      <joint_name>rg2_finger_joint2</joint_name>
      <topic>/rg2/finger2_cmd</topic>
      <p_gain>8.0</p_gain><i_gain>0.1</i_gain><d_gain>0.4</d_gain>
      <initial_position>0.0</initial_position>
    </plugin>
  </gazebo>

</robot>
